Workbook
Name Транспорт: 'Справочники'!$C$2:$J$2
Name Подарки: 'Справочники'!$C$6:$J$6
Name Продукты: 'Справочники'!$C$7:$J$7
Name Рестораны: 'Справочники'!$C$4:$J$4
Name Алкоголь: 'Справочники'!$C$5:$J$5
Name Еда: 'Справочники'!$C$3:$J$3

Sheet Дашборд
B2: Последние расходы внесены | D2: =MAX('Повседневные'!C:C) -> 43279
B3: Средний расход за текущий месяц | D3: =H66/DAY(D2) -> 2351.9643 | E3: =IF(D3>D4,"ТРАНЖИРА","В НОРМЕ") -> ТРАНЖИРА
B4: Лимит расхода в день | D4: 2000
E23: AVG в месяц | G23: Месяц | H23: Повседневные | I23: В день | J23: Крупные | K23: Квартира | L23: Итого | N23: Итого Повседневные | O23: =H36 -> 324074 | P23: руб.
E24: =D24*$O$31 -> 10398.741 | G24: Январь | H24: {=TRANSPOSE(C72:N72)} -> 47443 | I24: {=TRANSPOSE(C69:N69)} -> 1530.4194 | J24: {=TRANSPOSE(C73:N73)} -> 20000 | K24: {=TRANSPOSE(C74:N74)} -> 37500 | L24: {=TRANSPOSE(C75:N75)} -> 104943 | N24: Итого Крупные | O24: =J36 -> 113800 | P24: руб.
E25: =D25*$O$31 -> 8706.3436 | G25: Февраль | H25: 17025 | I25: 1151.2143 | J25: 18000 | K25: 43500 | L25: 78525 | N25: Итого Квартира | O25: =K36 -> 267300 | P25: руб.
E26: =D26*$O$31 -> 7702.081 | G26: Март | H26: 59263 | I26: 1330.4409 | J26: 9000 | K26: 37900 | L26: 106163 | N26: Итого все расхолы | O26: =L36 -> 705174 | P26: руб.
E27: =D27*$O$31 -> 7522.1442 | G27: Апрель | H27: 84558 | I27: 1735.7417 | J27: 38000 | K27: 75700 | L27: 198258
E28: =D28*$O$31 -> 5213.0407 | G28: Май | H28: 49930 | I28: 1665.929 | J28: 13300 | K28: 37700 | L28: 100930 | N28: Дней прошло | O28: =(MAX('Повседневные'!C:C)-'Повседневные'!C2)+1 -> 178 | P28: дней
E29: =D29*$O$31 -> 4573.6072 | F29: → | G29: Июнь | H29: 65855 | I29: 1800.4111 | J29: 15500 | K29: 35000 | L29: 116355 | N29: из них без трат | O29: =COUNTIF('Повседневные'!D:D,"Нет расходов") -> 16 | P29: дней
E30: =D30*$O$31 -> 4571.7275 | G30: Июль | N30: Средний расход за день | O30: =O23/O28 -> 1820.6404 | P30: руб.
E31: =D31*$O$31 -> 4283.111 | G31: Август | N31: Средний расход в месяц | O31: =O30*AVERAGE('Справочники'!C29:C40) -> 55377.814 | P31: руб.
E32: =D32*$O$31 -> 1043.3942 | G32: Сентябрь | N32: с учетом крупных расходов | O32: =((O23+O24)/O28)*AVERAGE('Справочники'!C29:C40) -> 74823.975 | P32: руб.
E33: =D33*$O$31 -> 666.43258 | G33: Октябрь | N33: с учетом всех расходов | O33: =((O23+O24+O25)/O28)*AVERAGE('Справочники'!C29:C40) -> 120500.24 | P33: руб.
E34: =D34*$O$31 -> 525.45646 | G34: Ноябрь
E35: =D35*$O$31 -> 171.73455 | G35: Декабрь
E36: =SUM(E24:E35) -> 55377.814 | G36: Год 1 | H36: =SUM(H24:H35) -> 324074 | I36: =AVERAGE(I24:I35) -> 1535.6927 | J36: =SUM(J24:J35) -> 113800 | K36: =SUM(K24:K35) -> 267300 | L36: =SUM(L24:L35) -> 705174
B38: Распределение Повседневных расходов по дням недели
B39: День недели | C39: Всего (руб.) | D39: Аллокация на день
B40: ПН | C40: =SUMIF('Повседневные'!A:A,2,'Повседневные'!G:G) -> 45959 | D40: =C40/SUM($C$40:$C$46) -> 0.14181638
B41: ВТ | C41: =SUMIF('Повседневные'!A:A,3,'Повседневные'!G:G) -> 33821 | D41: =C41/SUM($C$40:$C$46) -> 0.10436197
B42: СР | C42: =SUMIF('Повседневные'!A:A,4,'Повседневные'!G:G) -> 34543 | D42: =C42/SUM($C$40:$C$46) -> 0.10658985
B43: ЧТ | C43: =SUMIF('Повседневные'!A:A,5,'Повседневные'!G:G) -> 37606 | D43: =C43/SUM($C$40:$C$46) -> 0.1160414
B44: ПТ | C44: =SUMIF('Повседневные'!A:A,6,'Повседневные'!G:G) -> 72854 | D44: =C44/SUM($C$40:$C$46) -> 0.22480668
B45: СБ | C45: =SUMIF('Повседневные'!A:A,7,'Повседневные'!G:G) -> 45618 | D45: =C45/SUM($C$40:$C$46) -> 0.14076415
B46: ВС | C46: =SUMIF('Повседневные'!A:A,1,'Повседневные'!G:G) -> 53673 | D46: =C46/SUM($C$40:$C$46) -> 0.16561958
B47: Будни | C47: =SUM(C40:C44) -> 224783 | D47: =C47/SUM(C40:C46) -> 0.69361627
B48: Выходные | C48: =C45+C46 -> 99291 | D48: =C48/SUM(C40:C46) -> 0.30638373
B50: Примечание: С каждым новыс месяцем данная таблица будет расширяться вправо на один столбец
B51: Повседневные расходы | C51: 1 | D51: 2 | E51: 3 | F51: 4 | G51: 5 | H51: 6
I67: Сюда нужно будет протягивать формулы по мере увеличения месяце в сводной таблице выше
B68: Коэффициент трат в месяц | C68: =C66/$O$31 -> 0.85671493 | D68: =D66/$O$31 -> 0.30743359 | E68: =E66/$O$31 -> 1.0701578 | F68: =F66/$O$31 -> 1.5269292 | G68: =G66/$O$31 -> 0.90162462 | H68: =H66/$O$31 -> 1.1891947
B69: Средний расход в месяц | C69: =C70/VLOOKUP(C53,'Справочники'!$A$28:$C$40,3) -> 1530.4194 | D69: =D70/VLOOKUP(D53,'Справочники'!$A$28:$C$40,3) -> 1151.2143 | E69: =E70/VLOOKUP(E53,'Справочники'!$A$28:$C$40,3) -> 1330.4409 | F69: =F70/VLOOKUP(F53,'Справочники'!$A$28:$C$40,3) -> 1735.7417 | G69: =G70/VLOOKUP(G53,'Справочники'!$A$28:$C$40,3) -> 1665.929 | H69: =H70/VLOOKUP(H53,'Справочники'!$A$28:$C$40,3) -> 1800.4111
B70: Средний расход накоп. итогом | C70: =C66 -> 47443 | D70: =SUM($C$66:D66)/D51 -> 32234 | E70: =SUM($C$66:E66)/E51 -> 41243.667 | F70: =SUM($C$66:F66)/F51 -> 52072.25 | G70: =SUM($C$66:G66)/G51 -> 51643.8 | H70: =SUM($C$66:H66)/H51 -> 54012.333
B72: Повседневные | C72: =C66 -> 47443 | D72: =D66 -> 17025 | E72: =E66 -> 59263 | F72: =F66 -> 84558 | G72: =G66 -> 49930 | H72: =H66 -> 65855
B73: Крупные расходы | C73: =SUMIF('Крупные'!$B:$B,C53,'Крупные'!$E:$E) -> 20000 | D73: =SUMIF('Крупные'!$B:$B,D53,'Крупные'!$E:$E) -> 18000 | E73: =SUMIF('Крупные'!$B:$B,E53,'Крупные'!$E:$E) -> 9000 | F73: =SUMIF('Крупные'!$B:$B,F53,'Крупные'!$E:$E) -> 38000 | G73: =SUMIF('Крупные'!$B:$B,G53,'Крупные'!$E:$E) -> 13300 | H73: =SUMIF('Крупные'!$B:$B,H53,'Крупные'!$E:$E) -> 15500
B74: Квартира | C74: =SUMIF('Квартира'!$B:$B,C53,'Квартира'!$F:$F) -> 37500 | D74: =SUMIF('Квартира'!$B:$B,D53,'Квартира'!$F:$F) -> 43500 | E74: =SUMIF('Квартира'!$B:$B,E53,'Квартира'!$F:$F) -> 37900 | F74: =SUMIF('Квартира'!$B:$B,F53,'Квартира'!$F:$F) -> 75700 | G74: =SUMIF('Квартира'!$B:$B,G53,'Квартира'!$F:$F) -> 37700 | H74: =SUMIF('Квартира'!$B:$B,H53,'Квартира'!$F:$F) -> 35000
B75: Итого в месяц | C75: =C66+C73+C74 -> 104943 | D75: =D66+D73+D74 -> 78525 | E75: =E66+E73+E74 -> 106163 | F75: =F66+F73+F74 -> 198258 | G75: =G66+G73+G74 -> 100930 | H75: =H66+H73+H74 -> 116355

Sheet Повседневные
A1: DW | B1: Month | C1: Дата | D1: Наименование | E1: Категория | F1: Подкатегория | G1: Стоимость | H1: Комментарий | I1: Автоматический список подкатегорий. Заполняется при выборе основной категории.
A2: =WEEKDAY(C2) -> 3 | B2: =MONTH(C2) -> 1 | C2: 43102 | D2: Такси | E2: Транспорт | F2: Такси | G2: 676 | I2: =IFERROR(INDIRECT(E2),"") -> Такси | J2: Автобус | K2: Метро | L2: Электричка | M2: Другой транспорт
A3: =WEEKDAY(C3) -> 3 | B3: =MONTH(C3) -> 1 | C3: 43102 | D3: Пиво в баре | E3: Рестораны | F3: Бар | G3: 900 | I3: =IFERROR(INDIRECT(E3),"") -> Бар | J3: Ресторан | K3: Бургерная | L3: Доставка | M3: Кальянная
A4: =WEEKDAY(C4) -> 3 | B4: =MONTH(C4) -> 1 | C4: 43102 | D4: Обед | E4: Еда | F4: Еда вне работы | G4: 700 | I4: =IFERROR(INDIRECT(E4),"") -> Обед (работа) | J4: Перекус | K4: Фаст-Фуд | L4: Сладости | M4: Еда вне работы
A5: =WEEKDAY(C5) -> 3 | B5: =MONTH(C5) -> 1 | C5: 43102 | D5: Перекус | E5: Еда | F5: Еда вне работы | G5: 350 | I5: =IFERROR(INDIRECT(E5),"") -> Обед (работа) | J5: Перекус | K5: Фаст-Фуд | L5: Сладости | M5: Еда вне работы
A6: =WEEKDAY(C6) -> 3 | B6: =MONTH(C6) -> 1 | C6: 43102 | D6: Кальянная | E6: Рестораны | F6: Кальянная | G6: 600 | I6: =IFERROR(INDIRECT(E6),"") -> Бар | J6: Ресторан | K6: Бургерная | L6: Доставка | M6: Кальянная
A7: =WEEKDAY(C7) -> 3 | B7: =MONTH(C7) -> 1 | C7: 43102 | D7: Такси | E7: Транспорт | F7: Такси | G7: 250 | I7: =IFERROR(INDIRECT(E7),"") -> Такси | J7: Автобус | K7: Метро | L7: Электричка | M7: Другой транспорт
A8: =WEEKDAY(C8) -> 4 | B8: =MONTH(C8) -> 1 | C8: 43103 | D8: Такси | E8: Транспорт | F8: Такси | G8: 690 | I8: =IFERROR(INDIRECT(E8),"") -> Такси | J8: Автобус | K8: Метро | L8: Электричка | M8: Другой транспорт
A9: =WEEKDAY(C9) -> 4 | B9: =MONTH(C9) -> 1 | C9: 43103 | D9: Обед | E9: Еда | F9: Еда вне работы | G9: 700 | I9: =IFERROR(INDIRECT(E9),"") -> Обед (работа) | J9: Перекус | K9: Фаст-Фуд | L9: Сладости | M9: Еда вне работы
A10: =WEEKDAY(C10) -> 4 | B10: =MONTH(C10) -> 1 | C10: 43103 | D10: Пиво и пицца | E10: Алкоголь | F10: Пиво | G10: 550 | I10: =IFERROR(INDIRECT(E10),"") -> Вино | J10: Пиво | K10: Сидр | L10: Крепкое | M10: Закуски
A11: =WEEKDAY(C11) -> 5 | B11: =MONTH(C11) -> 1 | C11: 43104 | D11: Такси | E11: Транспорт | F11: Такси | G11: 500 | I11: =IFERROR(INDIRECT(E11),"") -> Такси | J11: Автобус | K11: Метро | L11: Электричка | M11: Другой транспорт
A12: =WEEKDAY(C12) -> 5 | B12: =MONTH(C12) -> 1 | C12: 43104 | D12: Макдоналдс | E12: Еда | F12: Фаст-Фуд | G12: 400 | I12: =IFERROR(INDIRECT(E12),"") -> Обед (работа) | J12: Перекус | K12: Фаст-Фуд | L12: Сладости | M12: Еда вне работы
A13: =WEEKDAY(C13) -> 6 | B13: =MONTH(C13) -> 1 | C13: 43105 | D13: Такси | E13: Транспорт | F13: Такси | G13: 200 | I13: =IFERROR(INDIRECT(E13),"") -> Такси | J13: Автобус | K13: Метро | L13: Электричка | M13: Другой транспорт
... A16: =WEEKDAY(C16) -> 7 | B16: =MONTH(C16) -> 1 | C16: 43106 | D16: Пиво и креветки | E16: Алкоголь | F16: Пиво | G16: 800 | I16: =IFERROR(INDIRECT(E16),"") -> Вино | J16: Пиво | K16: Сидр | L16: Крепкое | M16: Закуски
A17: =WEEKDAY(C17) -> 7 | B17: =MONTH(C17) -> 1 | C17: 43106 | D17: Продукты | E17: Продукты | G17: 300 | I17: =IFERROR(INDIRECT(E17),"")
A18: =WEEKDAY(C18) -> 7 | B18: =MONTH(C18) -> 1 | C18: 43106 | D18: Для бритья | E18: Здоровье, красота, гигиена | G18: 500 | I18: =IFERROR(INDIRECT(E18),"")
A19: =WEEKDAY(C19) -> 7 | B19: =MONTH(C19) -> 1 | C19: 43106 | D19: Такси | E19: Транспорт | F19: Такси | G19: 136 | I19: =IFERROR(INDIRECT(E19),"") -> Такси | J19: Автобус | K19: Метро | L19: Электричка | M19: Другой транспорт
A20: =WEEKDAY(C20) -> 1 | B20: =MONTH(C20) -> 1 | C20: 43107 | D20: Такси | E20: Транспорт | F20: Такси | G20: 146 | I20: =IFERROR(INDIRECT(E20),"") -> Такси | J20: Автобус | K20: Метро | L20: Электричка | M20: Другой транспорт
A21: =WEEKDAY(C21) -> 1 | B21: =MONTH(C21) -> 1 | C21: 43107 | D21: Вода | E21: Еда | F21: Перекус | G21: 50 | I21: =IFERROR(INDIRECT(E21),"") -> Обед (работа) | J21: Перекус | K21: Фаст-Фуд | L21: Сладости | M21: Еда вне работы
A22: =WEEKDAY(C22) -> 1 | B22: =MONTH(C22) -> 1 | C22: 43107 | D22: Ресторан Питер | E22: Рестораны | F22: Ресторан | G22: 1200 | I22: =IFERROR(INDIRECT(E22),"") -> Бар | J22: Ресторан | K22: Бургерная | L22: Доставка | M22: Кальянная
A23: =WEEKDAY(C23) -> 1 | B23: =MONTH(C23) -> 1 | C23: 43107 | D23: Пушкинский музей | E23: Кино, театры, музеи | G23: 300 | I23: =IFERROR(INDIRECT(E23),"")
A24: =WEEKDAY(C24) -> 1 | B24: =MONTH(C24) -> 1 | C24: 43107 | D24: Квест | E24: Кино, театры, музеи | G24: 800 | I24: =IFERROR(INDIRECT(E24),"")
A25: =WEEKDAY(C25) -> 1 | B25: =MONTH(C25) -> 1 | C25: 43107 | D25: Блэк стар бургер | E25: Еда | F25: Фаст-фуд | G25: 490 | I25: =IFERROR(INDIRECT(E25),"") -> Обед (работа) | J25: Перекус | K25: Фаст-Фуд | L25: Сладости | M25: Еда вне работы
A26: =WEEKDAY(C26) -> 1 | B26: =MONTH(C26) -> 1 | C26: 43107 | D26: Вино | E26: Алкоголь | F26: Вино | G26: 500 | I26: =IFERROR(INDIRECT(E26),"") -> Вино | J26: Пиво | K26: Сидр | L26: Крепкое | M26: Закуски
A27: =WEEKDAY(C27) -> 1 | B27: =MONTH(C27) -> 1 | C27: 43107 | D27: Кино + вода | E27: Кино, театры, музеи | G27: 650 | I27: =IFERROR(INDIRECT(E27),"")
A28: =WEEKDAY(C28) -> 1 | B28: =MONTH(C28) -> 1 | C28: 43107 | D28: Шоколадка | E28: Еда | F28: Сладости | G28: 166 | I28: =IFERROR(INDIRECT(E28),"") -> Обед (работа) | J28: Перекус | K28: Фаст-Фуд | L28: Сладости | M28: Еда вне работы
A29: =WEEKDAY(C29) -> 2 | B29: =MONTH(C29) -> 1 | C29: 43108 | D29: Сидр | E29: Алкоголь | F29: Сидр | G29: 170 | I29: =IFERROR(INDIRECT(E29),"") -> Вино | J29: Пиво | K29: Сидр | L29: Крепкое | M29: Закуски
A30: =WEEKDAY(C30) -> 2 | B30: =MONTH(C30) -> 1 | C30: 43108 | D30: Домой | E30: Здоровье, красота, гигиена | G30: 1200 | I30: =IFERROR(INDIRECT(E30),"")
A31: =WEEKDAY(C31) -> 2 | B31: =MONTH(C31) -> 1 | C31: 43108 | D31: Коллеге | E31: Подарки | F31: Работа | G31: 300 | I31: =IFERROR(INDIRECT(E31),"") -> Родственники | J31: Друзья | K31: Работа
A32: =WEEKDAY(C32) -> 3 | B32: =MONTH(C32) -> 1 | C32: 43109 | D32: Обед | E32: Еда | F32: Обед (работа) | G32: 393 | I32: =IFERROR(INDIRECT(E32),"") -> Обед (работа) | J32: Перекус | K32: Фаст-Фуд | L32: Сладости | M32: Еда вне работы
A33: =WEEKDAY(C33) -> 3 | B33: =MONTH(C33) -> 1 | C33: 43109 | D33: Apple music | E33: Творчество, книги, обучение | G33: 169 | I33: =IFERROR(INDIRECT(E33),"")
A34: =WEEKDAY(C34) -> 5 | B34: =MONTH(C34) -> 1 | C34: 43111 | D34: Обед | E34: Еда | F34: Обед (работа) | G34: 296 | I34: =IFERROR(INDIRECT(E34),"") -> Обед (работа) | J34: Перекус | K34: Фаст-Фуд | L34: Сладости | M34: Еда вне работы
A35: =WEEKDAY(C35) -> 5 | B35: =MONTH(C35) -> 1 | C35: 43111 | D35: Сестре | E35: Подарки | F35: Родственники | G35: 3000 | I35: =IFERROR(INDIRECT(E35),"") -> Родственники | J35: Друзья | K35: Работа
A36: =WEEKDAY(C36) -> 6 | B36: =MONTH(C36) -> 1 | C36: 43112 | D36: Электричка | E36: Транспорт | F36: Электричка | G36: 88 | I36: =IFERROR(INDIRECT(E36),"") -> Такси | J36: Автобус | K36: Метро | L36: Электричка | M36: Другой транспорт
A37: =WEEKDAY(C37) -> 6 | B37: =MONTH(C37) -> 1 | C37: 43112 | D37: Дима | E37: Подарки | F37: Работа | G37: 300 | I37: =IFERROR(INDIRECT(E37),"") -> Родственники | J37: Друзья | K37: Работа
A38: =WEEKDAY(C38) -> 6 | B38: =MONTH(C38) -> 1 | C38: 43112 | D38: Жевачка | E38: Еда | F38: Сладости | G38: 50 | I38: =IFERROR(INDIRECT(E38),"") -> Обед (работа) | J38: Перекус | K38: Фаст-Фуд | L38: Сладости | M38: Еда вне работы
A39: =WEEKDAY(C39) -> 6 | B39: =MONTH(C39) -> 1 | C39: 43112 | D39: Вино | E39: Алкоголь | F39: Вино | G39: 1000 | I39: =IFERROR(INDIRECT(E39),"") -> Вино | J39: Пиво | K39: Сидр | L39: Крепкое | M39: Закуски
A40: =WEEKDAY(C40) -> 6 | B40: =MONTH(C40) -> 1 | C40: 43112 | D40: Такси | E40: Транспорт | F40: Такси | G40: 134 | I40: =IFERROR(INDIRECT(E40),"") -> Такси | J40: Автобус | K40: Метро | L40: Электричка | M40: Другой транспорт
A41: =WEEKDAY(C41) -> 6 | B41: =MONTH(C41) -> 1 | C41: 43112 | D41: Печеньки | E41: Еда | F41: Сладости | G41: 421 | I41: =IFERROR(INDIRECT(E41),"") -> Обед (работа) | J41: Перекус | K41: Фаст-Фуд | L41: Сладости | M41: Еда вне работы
A42: =WEEKDAY(C42) -> 7 | B42: =MONTH(C42) -> 1 | C42: 43113 | D42: Нет расходов | G42: 0 | I42: =IFERROR(INDIRECT(E42),"")
...

Sheet Крупные
B1: MM | C1: Дата | D1: Покупка | E1: Сумма
B2: =MONTH(C2) -> 1 | C2: 43115 | D2: Абонемент в спорт зал | E2: 20000
B3: =MONTH(C3) -> 2 | C3: 43136 | D3: Пальто | E3: 18000
B4: =MONTH(C4) -> 3 | C4: 43166 | D4: Билеты в Берлин | E4: 9000
B5: =MONTH(C5) -> 4 | C5: 43192 | D5: Отель в Берлине | E5: 12000
B6: =MONTH(C6) -> 4 | C6: 43207 | D6: Курсы английского | E6: 26000
B7: =MONTH(C7) -> 5 | C7: 43587 | D7: Билеты в Питер | E7: 5500
B8: =MONTH(C8) -> 5 | C8: 43606 | D8: Квартира Питер | E8: 7800
B9: =MONTH(C9) -> 6 | C9: 43628 | D9: Кожаная сумка | E9: 15500
C18: В данной таблице фиксируются все расходы, которые не имеют повседневный характер

Sheet Квартира
B1: MM | C1: Дата | D1: Категори | E1: Описание | F1: Сумма
B2: =MONTH(C2) -> 1 | C2: 43106 | D2: Ипотека | F2: 35000
B3: =MONTH(C3) -> 1 | C3: 43130 | D3: ЖКХ | F3: 2500
B4: =MONTH(C4) -> 2 | C4: 43133 | D4: Все для дома | E4: Подушки и одеяла | F4: 5700
B5: =MONTH(C5) -> 2 | C5: 43137 | D5: Ипотека | F5: 35000
B6: =MONTH(C6) -> 2 | C6: 43159 | D6: ЖКХ | F6: 2800
B7: =MONTH(C7) -> 3 | C7: 43165 | D7: Ипотека | F7: 35000
B8: =MONTH(C8) -> 3 | C8: 43189 | D8: ЖКХ | F8: 2900
B9: =MONTH(C9) -> 4 | C9: 43196 | D9: Ипотека | F9: 35000
B10: =MONTH(C10) -> 4 | C10: 43205 | D10: Ремонт | E10: Входная дверь | F10: 29000
B11: =MONTH(C11) -> 4 | C11: 43211 | D11: Прочие расходы | E11: Страховка Ипотека | F11: 8900
B12: =MONTH(C12) -> 4 | C12: 43220 | D12: ЖКХ | F12: 2800
B13: =MONTH(C13) -> 5 | C13: 43226 | D13: Ипотека | F13: 35000
B14: =MONTH(C14) -> 5 | C14: 43250 | D14: ЖКХ | F14: 2700
B15: =MONTH(C15) -> 6 | C15: 43257 | D15: Ипотека | F15: 35000

Sheet Справочники
B1: Категории повседневных расходов | C1: Подкатегории
B2: Транспорт | C2: Такси | D2: Автобус | E2: Метро | F2: Электричка | G2: Другой транспорт
B3: Еда | C3: Обед (работа) | D3: Перекус | E3: Фаст-Фуд | F3: Сладости | G3: Еда вне работы
B4: Рестораны | C4: Бар | D4: Ресторан | E4: Бургерная | F4: Доставка | G4: Кальянная
B5: Алкоголь | C5: Вино | D5: Пиво | E5: Сидр | F5: Крепкое | G5: Закуски
B6: Подарки | C6: Родственники | D6: Друзья | E6: Работа
B7: Продукты
B8: Здоровье, красота, гигиена
B9: Одежда
B10: Творчество, книги, обучение
B11: Кино, театры, музеи
B12: Связь
B13: Прочее
B15: В колонку B добавляем свои категории или переименовываем текущие
B16: Напротив каждой категории можно указать до 8 подкатегорий
B17: При выборе основной категории на вкладке "Повседневные" список подкатегорий загрузится автоматически
B19: Категории расходов на квартиру
B20: Ремонт
... B28: Дней в году
A29: 1 | B29: Январь | C29: 31
A30: 2 | B30: Февраль | C30: 28
A31: 3 | B31: Март | C31: 31
A32: 4 | B32: Апрель | C32: 30
A33: 5 | B33: Май | C33: 31
A34: 6 | B34: Июнь | C34: 30
A35: 7 | B35: Июль | C35: 31
A36: 8 | B36: Август | C36: 31
A37: 9 | B37: Сентябрь | C37: 30
A38: 10 | B38: Октябрь | C38: 31
A39: 11 | B39: Ноябрь | C39: 30
A40: 12 | B40: Декабрь | C40: 31
