Workbook

Sheet Бюджет 2019
A1: Бюджет на 2019 год | Q1: Андрей | R1: 11.07 – 09.08.2019 | W1: Андрей | X1: 28.10 – 11.11.2019
H2: Ирина | I2: 25.03 - 04.04.2019 | Q2: Ирина | R2: 22.07 - 23.08.2019
C3: План на | D3: =IF(D5<10000,"!Мало!","") | E3: =IF(E5<10000,"!Мало!","") | F3: =IF(F5<10000,"!Мало!","") | G3: =IF(G5<10000,"!Мало!","") | H3: =IF(H5<10000,"!Мало!","") | I3: =IF(I5<10000,"!Мало!","") | J3: =IF(J5<10000,"!Мало!","") | K3: =IF(K5<10000,"!Мало!","") | ... AA3: =IF(AA5<10000,"!Мало!","") -> !Мало!
C4: 2 недели | D4: 1/2 январь | E4: 2/2 январь | F4: 1/2 февраль | G4: 2/2 февраль | H4: 1/2 март | I4: 2/2 март | J4: 1/2 апрель | K4: 2/2 апрель | L4: 1/2 май | M4: 2/2 май | N4: 1/2 июнь | O4: 2/2 июнь | P4: 1/2 июль | Q4: 2/2 июль | R4: 1/2 август | S4: 2/2 август | T4: 1/2 сентябрь | U4: 2/2 сентябрь | V4: 1/2 октябрь | W4: 2/2 октябрь | X4: 1/2 ноябрь | Y4: 2/2 ноябрь | Z4: 1/2 декабрь | AA4: 2/2 декабрь
A5: Остаток денег на начало | B5: Итого | C5: 61000 | D5: =40000+17000 -> 57000 | E5: =D5+D16-D47 -> 65561 | F5: =40700+14610 -> 55310 | G5: 35900 | H5: 56300 | I5: =12500+5400+2500 -> 20400 | J5: =14160+20000+40000 -> 74160 | K5: =59400+17720 -> 77120 | L5: =K5+K16-K47-50000 -> 44445 | M5: =L5+L16-L47+30000 -> 62717 | N5: =31225 -> 31225 | O5: 5410 | P5: 7500 | Q5: =P5+P16-P47 -> 82757 | R5: =Q5+Q16-Q47 -> 194746 | S5: =119000+41200+15100+15200+25000+6000 -> 221500 | T5: =S5+S16-S47 -> 238288 | U5: =76400+15260+50510+1500 -> 143670 | V5: =U5+U16-U47 -> 145356 | W5: =51300 -> 51300 | X5: =50000+27000 -> 77000 | Y5: =51800+21700 -> 73500 | Z5: =30000+7200+25000+1900-11300 -> 52800 | AA5: =7800+2300-17000 -> -6900
A6: Доходы
A8: Аванс Мой | B8: =SUM(D8:AA8) -> 240332 | C8: 0 | D8: =20200+14750 -> 34950 | E8: 0 | F8: =20250+3500 -> 23750 | G8: 0 | H8: 20200 | I8: 0 | J8: 20200 | K8: 0 | L8: 20200 | M8: 0 | N8: 20200 | O8: 0 | P8: 20200 | Q8: 0 | R8: 15095 | S8: 0 | T8: 7550 | U8: 0 | V8: 20750 | W8: 0 | X8: 20750 | Y8: 0 | Z8: 8300 | AA8: 8187
A9: Зарплата Мой | B9: =SUM(D9:AA9) -> 678803 | C9: 0 | D9: 0 | E9: 54000 | F9: 0 | G9: 56450 | H9: 0 | I9: 66050 | J9: 0 | K9: 64850 | L9: 0 | M9: 64480 | N9: 0 | O9: 64480 | P9: 0 | Q9: =64970+1572 -> 66542 | R9: 0 | S9: 41300 | T9: 0 | U9: 37700 | V9: 0 | W9: 59460 | X9: 0 | Y9: 50990 | Z9: 0 | AA9: 52501
A10: Отпускные Мой+Супруга | B10: =SUM(D10:AA10) -> 283040 | C10: 0 | D10: 0 | E10: 0 | F10: 0 | G10: 0 | H10: 0 | I10: 27000 | J10: 0 | K10: 0 | L10: 0 | M10: 0 | N10: 0 | O10: 0 | P10: =87363+11877 -> 99240 | Q10: =12780+81860 -> 94640 | R10: 0 | S10: 0 | T10: 0 | U10: 0 | V10: 20200 | W10: 41960 | X10: 0 | Y10: 0 | Z10: 0 | AA10: 0
A11: Аванс Супруга | B11: =SUM(D11:AA11) -> 223900 | C11: 0 | D11: =22900+15000 -> 37900 | E11: 0 | F11: =18900+2200 -> 21100 | G11: 0 | H11: 18900 | I11: 0 | J11: 18900 | K11: 0 | L11: 12200 | M11: 0 | N11: 18900 | O11: 0 | P11: 18900 | Q11: 0 | R11: 18900 | S11: 0 | T11: 0 | U11: 0 | V11: 19400 | W11: 0 | X11: 19400 | Y11: 0 | Z11: 19400 | AA11: 0
A12: Зарплата Супруга | B12: =SUM(D12:AA12) -> 523375 | C12: 0 | D12: 0 | E12: 23700 | F12: 0 | G12: 53230 | H12: 0 | I12: 53230 | J12: 0 | K12: 44150 | L12: 0 | M12: 44635 | N12: 0 | O12: 46400 | P12: 0 | Q12: 52860 | R12: 0 | S12: 40350 | T12: 0 | U12: 32200 | V12: 0 | W12: 24280 | X12: 0 | Y12: 54190 | Z12: 0 | AA12: 54150
A13: Кэшбэк сервис | B13: =SUM(D13:AA13) -> 9242 | C13: 0 | D13: 737 | E13: 70 | F13: 620 | G13: 92 | H13: 0 | I13: =88 -> 88 | J13: 0 | K13: =324 -> 324 | L13: 0 | M13: 247 | N13: 0 | O13: 308 | P13: 0 | Q13: 195 | R13: 240 | S13: =235+750 -> 985 | T13: 85 | U13: 120 | V13: 0 | W13: =359+373+331 -> 1063 | X13: =90+68 -> 158 | Y13: =824+779 -> 1603 | Z13: =1081 -> 1081 | AA13: =300+125+334+467 -> 1226
A14: Долги \ Подарки | B14: =SUM(D14:AA14) -> 92000 | C14: 0 | D14: 0 | E14: =7000+5000+70000 -> 82000 | F14: 0 | G14: 0 | H14: 0 | I14: 0 | J14: 0 | K14: 0 | L14: 0 | M14: 0 | N14: 0 | O14: 0 | P14: 0 | Q14: 0 | R14: 0 | S14: 0 | T14: 0 | U14: 0 | V14: 0 | W14: 0 | X14: 0 | Y14: =5000+5000 -> 10000 | Z14: 0 | AA14: 0
A15: Выплата от ИФНС \ Прочее | B15: =SUM(D15:AA15) -> 7149 | C15: 0 | D15: 0 | E15: 0 | F15: 0 | G15: 0 | H15: 0 | I15: 0 | J15: 0 | K15: 0 | L15: 0 | M15: 0 | N15: 0 | O15: 5362 | P15: 0 | Q15: 0 | R15: 1787 | S15: 0 | T15: 0 | U15: 0 | V15: 0 | X15: 0 | Y15: 0 | Z15: 0 | AA15: 0
A16: Итого доходы: | D16: =SUM(D8:D15) -> 73587 | E16: =SUM(E8:E15) -> 159770 | F16: =SUM(F8:F15) -> 45470 | G16: =SUM(G8:G15) -> 109772 | H16: =SUM(H8:H15) -> 39100 | I16: =SUM(I8:I15) -> 146368 | J16: =SUM(J8:J14) -> 39100 | K16: =SUM(K8:K15) -> 109324 | L16: =SUM(L8:L15) -> 32400 | M16: =SUM(M8:M15) -> 109362 | N16: =SUM(N8:N15) -> 39100 | O16: =SUM(O8:O15) -> 116550 | P16: =SUM(P8:P15) -> 138340 | Q16: =SUM(Q8:Q15) -> 214237 | R16: =SUM(R8:R15) -> 36022 | ... X16: =SUM(X8:X15) -> 40308 | Y16: =SUM(Y8:Y15)-Y15 -> 116783 | Z16: =SUM(Z8:Z15) -> 28781 | AA16: =SUM(AA8:AA15) -> 116064
A18: Расходы
A19: Накопления (на погашение) 30%-Ипотека | B19: =SUM(D19:AA19) -> 350862 | C19: 12800 | D19: 7000 | E19: =23300+70000 -> 93300 | F19: 13600 | G19: 17800 | H19: 22200 | J19: 0 | K19: 22400 | L19: 9700 | M19: 17600 | N19: 11700 | O19: =19000+5362 -> 24362 | P19: 18900 | T19: 2200 | U19: 0 | V19: =ROUNDDOWN((V$16-SUM(V$14:V$15))*30%,-2)-V20 -> 18100 | W19: 22600 | X19: 12000 | Y19: 16400 | Z19: 8300 | AA19: 12700
A20: Ипотека 15.4 т.р. (ВТБ24 9,45%) | B20: =SUM(D20:AA20) -> 181000 | C20: 15100 | D20: 15000 | E20: 0 | G20: 15100 | H20: 0 | I20: 15100 | J20: 0 | K20: 15100 | L20: 0 | M20: 15100 | N20: 0 | O20: 15000 | P20: 0 | Q20: 15100 | S20: 15100 | T20: 0 | U20: 15100 | V20: 0 | W20: 15100 | X20: 0 | Y20: 15100 | Z20: 0 | AA20: 15100
A21: Доча Школа питание | B21: =SUM(D21:AA21) -> 13030 | C21: 0 | F21: 2200 | H21: 1000 | I21: 0 | J21: 2000 | K21: 0 | M21: 0 | N21: 0 | P21: 0 | U21: 1700 | V21: 2350 | W21: 0 | X21: 1800 | Y21: 0 | Z21: 1980 | AA21: 0
A22: Накопления (строительные) 9% | B22: =SUM(D22:AA22) -> 166600 | C22: 1600 | D22: 6600 | E22: 6900 | F22: 4000 | G22: 9800 | H22: 6600 | I22: 10600 | J22: 3500 | K22: 9800 | L22: 2900 | M22: 9800 | N22: 3500 | O22: 9900 | P22: 12400 | Q22: 19200 | R22: =ROUNDDOWN(R16*9%,-2) -> 3200 | S22: 7300 | T22: 600 | U22: =ROUNDDOWN(U16*9%,-2) -> 6300 | V22: =ROUNDDOWN(V16*9%,-2) -> 5400 | W22: 11300 | X22: 3600 | Y22: 9400 | Z22: 2400 | AA22: 1600
A23: Накопления (отпуск) 11% | B23: =SUM(D23:AA23) -> 229570 | C23: 11700 | D23: 8000 | E23: =8500+5000 -> 13500 | F23: 5000 | G23: 12000 | H23: 8100 | I23: 16000 | J23: 4300 | K23: 11900 | L23: 3500 | M23: 12000 | N23: =ROUNDDOWN(N16*11%,-2) -> 4300 | O23: =12100+5729+2941+10500 -> 31270 | P23: 0 | Q23: 23500 | R23: =ROUNDDOWN(R16*11%,-2) -> 3900 | S23: 9900 | T23: 800 | U23: 7600 | V23: 6600 | W23: 13800 | X23: 4400 | Y23: 11500 | Z23: 6000 | AA23: 11700
A24: Накопления (одежда) 6% | B24: =SUM(D24:AA24) -> 124700 | C24: 6300 | D24: 4400 | E24: =4600+7000 -> 11600 | F24: 2700 | G24: 6500 | H24: 4400 | I24: 8700 | J24: 2300 | K24: 6500 | L24: 1900 | M24: 6500 | N24: =ROUNDDOWN(N16*6%,-2) -> 2300 | O24: 6600 | P24: 8300 | Q24: 12800 | R24: =ROUNDDOWN(R16*6%,-2) -> 2100 | S24: 4800 | T24: 400 | U24: =ROUNDDOWN(U16*6%,-2) -> 4200 | V24: =ROUNDDOWN(V16*6%,-2) -> 3600 | W24: 7500 | X24: 2400 | Y24: 6300 | Z24: 1600 | AA24: 6300
A25: Коммуналка Квартира | B25: =SUM(D25:AA25) -> 19353 | C25: 1500 | Q25: 3000 | R25: 0 | S25: 3000 | T25: 4200 | U25: 0 | V25: 0 | W25: 2500 | X25: 0 | Y25: =1500+250+4078 -> 5828 | Z25: 0 | AA25: 825
A26: Доп. занятия Доча РЦДО | B26: =SUM(D26:AA26) -> 6141 | C26: 1573 | H26: 0 | I26: 0 | J26: 0 | K26: 0 | L26: 0 | M26: 0 | N26: 0 | P26: 0 | T26: 0 | U26: 1472 | V26: 0 | W26: 1573 | X26: 0 | Y26: 1523 | Z26: 0 | AA26: 1573
A27: Доп. занятия Сын РЦДО | B27: =SUM(D27:AA27) -> 9200 | C27: 2300 | H27: 0 | I27: 0 | J27: 0 | K27: 0 | L27: 0 | M27: 0 | N27: 0 | P27: 0 | T27: 0 | U27: 2300 | V27: 0 | W27: 2300 | X27: 0 | Y27: 2300 | Z27: 0 | AA27: 2300
A28: Оплата детского сада | B28: =SUM(D28:AA28) -> 43339 | C28: 4330 | E28: =1100+1550 -> 2650 | F28: 0 | G28: 4800 | H28: 0 | I28: =1170+2720 -> 3890 | J28: 0 | K28: =2010+3560 -> 5570 | L28: 0 | M28: 3975 | N28: 1500 | O28: =3230+1670 -> 4900 | P28: 0 | Q28: 0 | R28: =3910+640 -> 4550 | S28: 0 | T28: 0 | U28: =1190 -> 1190 | V28: 0 | W28: =204+2890 -> 3094 | X28: 0 | Y28: 2890 | Z28: 0 | AA28: =372+525+204+3229 -> 4330
A29: Оплата электроэнергии+газ | B29: =SUM(D29:AA29) -> 39076 | C29: 1255 | E29: =1710+260 -> 1970 | F29: 1000 | G29: =2590+300 -> 2890 | H29: 2550 | I29: =1595 -> 1595 | J29: 4150 | K29: =1600+200 -> 1800 | L29: 2375 | M29: =1260+500 -> 1760 | N29: 3500 | O29: 940 | P29: 0 | Q29: =1235+125 -> 1360 | R29: 350 | T29: 1520 | V29: 300 | W29: =1095+500 -> 1595 | X29: 1700 | Y29: =1870+3351 -> 5221 | Z29: 2500 | AA29: 0
A30: Оплата телефон+интернет | B30: =SUM(D30:AA30) -> 17979 | C30: 1600 | E30: 1000 | F30: 0 | G30: 1200 | I30: =1600+200 -> 1800 | J30: 200 | K30: 1600 | L30: 0 | M30: 1600 | N30: 200 | O30: 200 | P30: 200 | Q30: 1600 | S30: 1800 | T30: 0 | U30: 1600 | V30: 0 | W30: =79 -> 79 | X30: 0 | Y30: 1600 | Z30: =1100+600 -> 1700 | AA30: 1600
A31: Доп. занятия Доча Английский | B31: =SUM(D31:AA31) -> 1850 | C31: 0 | E31: 1850 | H31: 0 | I31: 0 | J31: 3000 | K31: 0 | L31: 0 | M31: 0 | N31: 0 | O31: -3000 | P31: 0 | T31: 0 | U31: 0 | V31: 0 | W31: 0 | X31: 0 | Y31: 0 | Z31: 0 | AA31: 0
A32: Доп. занятия Доча Радужка ИЗО | B32: =SUM(D32:AA32) -> 25100 | C32: 0 | E32: 5400 | H32: 2700 | I32: 0 | J32: 2700 | K32: 0 | L32: 2700 | M32: 0 | N32: 0 | P32: 0 | T32: 2900 | V32: 2900 | W32: 0 | X32: 2900 | Y32: 0 | Z32: 2900 | AA32: 0
A33: Доп. занятия Доча Продленка | B33: =SUM(D33:AA33) -> 32238 | C33: 0 | D33: 5796 | E33: 2800 | H33: 0 | I33: 0 | J33: 2130 | K33: 0 | L33: 0 | M33: 17997 | N33: 0 | P33: 0 | T33: 0 | V33: 0 | W33: 0 | X33: 0 | Y33: 0 | Z33: 3515 | AA33: 0
A34: Еда + бытовая химия | B34: =SUM(D34:AA34) -> 357227 | C34: 19000 | D34: =204+440+255-65-65-65-290+25+5493+345+160+541+212+320+2244+929+218+212+395+846+415+193+267+320+1923 -> 15472 | E34: =402+734+302+343+415+482+1080+241-180-180-180-180+364+90+427+1718+170+5303+845+320+408+445+401+563+412+236+155+80+1373+447+223+500+185+546 -> 18490 | F34: =420+447+325+396+189+395+29+414+320+1210+4598+315+964+600+417+362+320+327+465+477+913+2794+320+452+472+372+105+909 -> 19327 | G34: =497+100+246+422+491+1011+320+187+325+834+477+163+356+410+250+666+457+608+430+227+172+6168+190+487+461+152+2628 -> 18735 | H34: =62+480+462+292+520+507+160+287+320+460+643+433+228+296+729-440-440+3215+265+232-440 -> 8271 | I34: =457+166+320+440+193+613+124+812+5595+457+420+920+467+487+458+295+256+320+846+749+27+237+267+330+177 -> 15433 | J34: =235+213+434+2205+57+232+556+149+2960+185+392+247+250+227+93+320+167+3327+203+354+482+200+442+320+34+462+148+428+140 -> 15462 | K34: =167+277+659+100+185+346+270+155+282+452+495+447+63+320+1822+129+558+477+383+482+407+422+422+447+760+125+216 -> 10868 | L34: =477+934+81+320+320+120+2361+472+203+412+290+160+1496+189+2195+6854+697-479-479-439+502+60+480 -> 17226 | M34: =352+241+482+452+469+1040+459+454+144+332+320+471+487+18+190+30+257+143+85+236+636+422+492+201+30 -> 8443 | N34: =392+507+39+500+222+621+60+320+6341+885+257+452+1377+497+35+70+442+18+84+4190+171+467+65+320+1565+400 -> 20297 | O34: =22+537+3102+456+60+66+235+412+395+520-410+462+417+432+96+220+401+437+209+427+320+3208+103+422+212 -> 12761 | P34: =72+148+1159+270+512+157+603+387+938+447+517+320+322+28+496+660+354+405+277+674+472+48+449+205+214+259+1375 -> 11768 | Q34: =30+76+774+47+830+248+235+181+383+13+210+3449+210+263+30+712+641+409+1080+413+125 -> 10359 | R34: =1020+239+239+480+1741+2624+264+620+290+262+406 -> 8185 | S34: =245+113+269+267+1420+575+250+334+150+339+850+262+464+257+320+417+813+272+282+224+461+137+349+104+556+1118+359+61+492+140+473+308+160+160+1589 -> 14590 | T34: =472+493+462+79+334+880+397+356+2865+655+30+235+370+320+395+40+485+6639-550-550-550+487+60+598+1320+1281+455+848+427+641 -> 19974 | U34: =168+32+86+877+40+62+480+3881+255+61+107+160+216+15+488+1456+235+149+245+70+43+855+180+3726+25+190+75+75+217+320+510+452+193+280+140+437+339 -> 17140 | V34: =477+40+1752+180+437+320+385+150+157+165+347+507+232+170+718+270+155+186+222+78+610+50+1059+457+68+422+122+507+497+236+17+723 -> 11716 | W34: =472+131+4266+378+320+430+35+115+90+487+465+39+26+927+425+18+27+282+427+80+107+3164+195+35+17+320+439+343+110+516+282+83+392+85+1879+195+6238+185+716 -> 24741 | X34: =230+320+912+53+30+1129+468+150+24+976+180+320+1746+26+199+26+568+700+145+500+286+100+422+200+99+273 -> 10082 | Y34: =90+320+1126+729+760+1000+272+407+517+1703+460+29+154+90+265+320+688+265+2364+35+140+472+110-4*150+450+159+456+452+494+510 -> 14237 | Z34: =(59+510+169+472+244+160+880+412+43+199+62+467+320+242+3134-799+290+100+422+472+3743+342+567+256+395+457+519)+(364+213+158+162+159) -> 15193 | AA34: =(499+320+84+349+487+59+143+917+475+386+1493+2786-560-560+432+457+114+345+954+320+6294+166+462+265+377+497+308)+(262+196+130) -> 18457
A35: Автомобиль
A36: Бензин | B36: =SUM(D36:AA36) -> 23781 | C36: 1500 | D36: =1410 -> 1410 | F36: =940 -> 940 | G36: 1058 | J36: 1528 | L36: =1528 -> 1528 | M36: =1645 -> 1645 | N36: 1470 | P36: 1361 | Q36: =221 -> 221 | T36: =1227+28+28+1199+505 -> 2987 | U36: 1645 | V36: 1297 | X36: =1379+1175 -> 2554 | Y36: 1126 | Z36: =1248 -> 1248 | AA36: 1763
A37: Ремонт авто | B37: =SUM(D37:AA37) -> 22788 | E37: =625 -> 625 | F37: 5000 | G37: =1040+2000 -> 3040 | H37: 0 | J37: =1200+570+178+160 -> 2108 | K37: =3700+900+195 -> 4795 | L37: 0 | N37: =350 -> 350 | R37: 800 | S37: 550 | V37: =800+260 -> 1060 | X37: 260 | Y37: 1000 | Z37: =1700+1500 -> 3200
A38: Страхование/Налоги/Штрафы | B38: =SUM(D38:AA38) -> 15068 | H38: 6987 | L38: 0 | N38: =500+400 -> 900 | P38: 0 | W38: 530 | Y38: 4485 | Z38: 2166
A39: Дом
A40: Страхование/Налоги | B40: =SUM(D40:AA40) -> 15868 | C40: 0 | H40: 3800 | I40: 5400 | J40: 0 | K40: 0 | L40: 0 | P40: 0 | T40: 0 | X40: 3072 | Y40: 1418 | AA40: 2178
A41: Строительство | B41: =SUM(D41:AA41) -> 166609 | D41: =1205+188 -> 1393 | G41: =306 -> 306 | H41: 2500 | I41: 0 | J41: =23868+1139 -> 25007 | K41: =785+1800+25+11797+840+262 -> 15509 | L41: =672+16809+5275 -> 22756 | M41: =340+1956 -> 2296 | N41: =1550+1213+420+40+1129+150 -> 4502 | O41: =220+3737+330 -> 4287 | P41: =102+116+191+275+2545+1107+350+16700+934+112+219+218+372 -> 23241 | Q41: =(1240+259+1190+1033+835+187+460+255+197)+19364+(379-379+327+94+136)-10000+(1403+451) -> 17431 | S41: =170+338+1500+1921+2282 -> 6211 | T41: =2820+1240+664+306+2840+4425+15000-3000+192+10000+527+100 -> 35114 | U41: =-2000+453 -> -1547 | V41: =313 -> 313 | X41: =220+795+70+120+170 -> 1375 | Y41: =2722+2169+100 -> 4991 | Z41: =500+100 -> 600 | AA41: =262+62 -> 324
A42: Семья
...

Sheet Накопления 2019
B2: 1/2 январь | C2: 2/2 январь | D2: 1/2 февраль | E2: 2/2 февраль | F2: 1/2 март | G2: 2/2 март | H2: 1/2 апрель | I2: 2/2 апрель | J2: 1/2 май | K2: 2/2 май | L2: 1/2 июнь | M2: 2/2 июнь | N2: 1/2 июль | O2: 2/2 июль | P2: 1/2 август | Q2: 2/2 август | R2: 1/2 сентябрь | S2: 2/2 сентябрь | T2: 1/2 октябрь | U2: 2/2 октябрь | V2: 1/2 ноябрь | W2: 2/2 ноябрь | X2: 1/2 декабрь | Y2: 2/2 декабрь
A3: ='Бюджет 2019'!A22 -> Накопления (строительные) 9% | B3: =1400+'Бюджет 2019'!D22-'Бюджет 2019'!D41 -> 6607 | C3: =B3+'Бюджет 2019'!E22-'Бюджет 2019'!E41 -> 13507 | D3: =C3+'Бюджет 2019'!F22-'Бюджет 2019'!F41 -> 17507 | E3: =D3+'Бюджет 2019'!G22-'Бюджет 2019'!G41 -> 27001 | F3: =E3+'Бюджет 2019'!H22-'Бюджет 2019'!H41 -> 31101 | G3: =F3+'Бюджет 2019'!I22-'Бюджет 2019'!I41 -> 41701 | H3: =G3+'Бюджет 2019'!J22-'Бюджет 2019'!J41 -> 20194 | I3: =H3+'Бюджет 2019'!K22-'Бюджет 2019'!K41 -> 14485 | J3: =I3+'Бюджет 2019'!L22-'Бюджет 2019'!L41 -> -5371 | ... Y3: =X3+'Бюджет 2019'!AA22-'Бюджет 2019'!AA41 -> 1391
A4: ='Бюджет 2019'!A23 -> Накопления (отпуск) 11% | B4: =120000+68400 -> 188400 | C4: =B4+'Бюджет 2019'!E23-'Бюджет 2019'!E46 -> 201900 | D4: =C4+'Бюджет 2019'!F23-'Бюджет 2019'!F46 -> 202700 | E4: =D4+'Бюджет 2019'!G23-'Бюджет 2019'!G46 -> 213200 | F4: =E4+'Бюджет 2019'!H23-'Бюджет 2019'!H46 -> 221300 | G4: =F4+'Бюджет 2019'!I23-'Бюджет 2019'!I46 -> 92397 | H4: =G4+'Бюджет 2019'!J23-'Бюджет 2019'!J46 -> 78697 | I4: =H4+'Бюджет 2019'!K23-'Бюджет 2019'!K46 -> 90597 | J4: =I4+'Бюджет 2019'!L23-'Бюджет 2019'!L46 -> 58165 | ... Y4: =X4+'Бюджет 2019'!AA23-'Бюджет 2019'!AA46 -> 109114
A5: ='Бюджет 2019'!A24 -> Накопления (одежда) 6% | B5: =1800+'Бюджет 2019'!D24-'Бюджет 2019'!D43 -> -295 | C5: =B5+'Бюджет 2019'!E24-'Бюджет 2019'!E43 -> 4338 | D5: =C5+'Бюджет 2019'!F24-'Бюджет 2019'!F43 -> 7038 | E5: =D5+'Бюджет 2019'!G24-'Бюджет 2019'!G43 -> 8578 | F5: =E5+'Бюджет 2019'!H24-'Бюджет 2019'!H43 -> 8817 | G5: =F5+'Бюджет 2019'!I24-'Бюджет 2019'!I43 -> 3191 | H5: =G5+'Бюджет 2019'!J24-'Бюджет 2019'!J43 -> 1293 | I5: =H5+'Бюджет 2019'!K24-'Бюджет 2019'!K43 -> -11922 | J5: =I5+'Бюджет 2019'!L24-'Бюджет 2019'!L43 -> -11022 | ... Y5: =X5+'Бюджет 2019'!AA24-'Бюджет 2019'!AA43 -> -15113

Sheet Статистика месяц
B1: январь | C1: февраль | D1: март | E1: апрель | F1: май | G1: июнь | H1: июль | I1: август | J1: сентябрь | K1: октябрь | L1: ноябрь | M1: декабрь
A2: Доходы Работа | B2: ='Бюджет 2019'!E8+'Бюджет 2019'!E9+'Бюджет 2019'!E10+'Бюджет 2019'!E11+'Бюджет 2019'!E12+'Бюджет 2019'!D12+'Бюджет 2019'!D11+'Бюджет 2019'!D10+'Бюджет 2019'!D9+'Бюджет 2019'!D8 -> 150550 | C2: ='Бюджет 2019'!F8+'Бюджет 2019'!F9+'Бюджет 2019'!F10+'Бюджет 2019'!F11+'Бюджет 2019'!F12+'Бюджет 2019'!G12+'Бюджет 2019'!G11+'Бюджет 2019'!G10+'Бюджет 2019'!G9+'Бюджет 2019'!G8 -> 154530 | D2: ='Бюджет 2019'!H8+'Бюджет 2019'!H9+'Бюджет 2019'!H10+'Бюджет 2019'!H11+'Бюджет 2019'!H12+'Бюджет 2019'!I12+'Бюджет 2019'!I11+'Бюджет 2019'!I10+'Бюджет 2019'!I9+'Бюджет 2019'!I8 -> 185380 | E2: ='Бюджет 2019'!J8+'Бюджет 2019'!J9+'Бюджет 2019'!J10+'Бюджет 2019'!J11+'Бюджет 2019'!J12+'Бюджет 2019'!K12+'Бюджет 2019'!K11+'Бюджет 2019'!K10+'Бюджет 2019'!K9+'Бюджет 2019'!K8 -> 148100 | F2: ='Бюджет 2019'!L8+'Бюджет 2019'!L9+'Бюджет 2019'!L10+'Бюджет 2019'!L11+'Бюджет 2019'!L12+'Бюджет 2019'!M12+'Бюджет 2019'!M11+'Бюджет 2019'!M10+'Бюджет 2019'!M9+'Бюджет 2019'!M8 -> 141515 | G2: ='Бюджет 2019'!N8+'Бюджет 2019'!N9+'Бюджет 2019'!N10+'Бюджет 2019'!N11+'Бюджет 2019'!N12+'Бюджет 2019'!O12+'Бюджет 2019'!O11+'Бюджет 2019'!O10+'Бюджет 2019'!O9+'Бюджет 2019'!O8 -> 149980 | H2: ='Бюджет 2019'!Q8+'Бюджет 2019'!Q9+'Бюджет 2019'!Q10+'Бюджет 2019'!Q11+'Бюджет 2019'!Q12+'Бюджет 2019'!P12+'Бюджет 2019'!P11+'Бюджет 2019'!P10+'Бюджет 2019'!P9+'Бюджет 2019'!P8 -> 352382 | I2: ='Бюджет 2019'!R8+'Бюджет 2019'!R9+'Бюджет 2019'!R10+'Бюджет 2019'!R11+'Бюджет 2019'!R12+'Бюджет 2019'!S12+'Бюджет 2019'!S11+'Бюджет 2019'!S10+'Бюджет 2019'!S9+'Бюджет 2019'!S8 -> 115645 | J2: ='Бюджет 2019'!U8+'Бюджет 2019'!U9+'Бюджет 2019'!U10+'Бюджет 2019'!U11+'Бюджет 2019'!U12+'Бюджет 2019'!T12+'Бюджет 2019'!T11+'Бюджет 2019'!T10+'Бюджет 2019'!T9+'Бюджет 2019'!T8 -> 77450 | K2: ='Бюджет 2019'!V8+'Бюджет 2019'!V9+'Бюджет 2019'!V10+'Бюджет 2019'!V11+'Бюджет 2019'!V12+'Бюджет 2019'!W12+'Бюджет 2019'!W11+'Бюджет 2019'!W10+'Бюджет 2019'!W9+'Бюджет 2019'!W8 -> 186050 | L2: ='Бюджет 2019'!Y8+'Бюджет 2019'!Y9+'Бюджет 2019'!Y10+'Бюджет 2019'!Y11+'Бюджет 2019'!Y12+'Бюджет 2019'!X12+'Бюджет 2019'!X11+'Бюджет 2019'!X10+'Бюджет 2019'!X9+'Бюджет 2019'!X8 -> 145330 | M2: ='Бюджет 2019'!Z8+'Бюджет 2019'!Z9+'Бюджет 2019'!Z10+'Бюджет 2019'!Z11+'Бюджет 2019'!Z12+'Бюджет 2019'!AA12+'Бюджет 2019'!AA11+'Бюджет 2019'!AA10+'Бюджет 2019'!AA9+'Бюджет 2019'!AA8 -> 142538
A3: Доходы Прочие | B3: ='Бюджет 2019'!D13+'Бюджет 2019'!D14+'Бюджет 2019'!D15+'Бюджет 2019'!E13+'Бюджет 2019'!E14+'Бюджет 2019'!E15 -> 82807 | C3: ='Бюджет 2019'!F13+'Бюджет 2019'!F14+'Бюджет 2019'!F15+'Бюджет 2019'!G13+'Бюджет 2019'!G14+'Бюджет 2019'!G15 -> 712 | D3: ='Бюджет 2019'!H13+'Бюджет 2019'!H14+'Бюджет 2019'!H15+'Бюджет 2019'!I13+'Бюджет 2019'!I14+'Бюджет 2019'!I15 -> 88 | E3: ='Бюджет 2019'!J13+'Бюджет 2019'!J14+'Бюджет 2019'!J15+'Бюджет 2019'!K13+'Бюджет 2019'!K14+'Бюджет 2019'!K15 -> 324 | F3: ='Бюджет 2019'!L13+'Бюджет 2019'!L14+'Бюджет 2019'!L15+'Бюджет 2019'!M13+'Бюджет 2019'!M14+'Бюджет 2019'!M15 -> 247 | G3: ='Бюджет 2019'!N13+'Бюджет 2019'!N14+'Бюджет 2019'!N15+'Бюджет 2019'!O13+'Бюджет 2019'!O14+'Бюджет 2019'!Q15 -> 308 | H3: ='Бюджет 2019'!P13+'Бюджет 2019'!P14+'Бюджет 2019'!R15+'Бюджет 2019'!Q13+'Бюджет 2019'!Q14 -> 1982 | I3: ='Бюджет 2019'!R13+'Бюджет 2019'!R14+'Бюджет 2019'!S13+'Бюджет 2019'!S14+'Бюджет 2019'!S15 -> 1225 | J3: ='Бюджет 2019'!T13+'Бюджет 2019'!T14+'Бюджет 2019'!T15+'Бюджет 2019'!U13+'Бюджет 2019'!U14+'Бюджет 2019'!U15 -> 205 | K3: ='Бюджет 2019'!V13+'Бюджет 2019'!V14+'Бюджет 2019'!V15+'Бюджет 2019'!W13+'Бюджет 2019'!W14+'Бюджет 2019'!W15 -> 1063 | L3: ='Бюджет 2019'!X13+'Бюджет 2019'!X14+'Бюджет 2019'!X15+'Бюджет 2019'!Y13+'Бюджет 2019'!Y14+'Бюджет 2019'!Y15 -> 11761 | M3: ='Бюджет 2019'!AA13+'Бюджет 2019'!AA14+'Бюджет 2019'!AA15+'Бюджет 2019'!Z13+'Бюджет 2019'!Z14+'Бюджет 2019'!Z15 -> 2307
A4: Накопления | B4: ='Статистика понедельная'!B4+'Статистика понедельная'!C4 -> 151300 | C4: ='Статистика понедельная'!D4+'Статистика понедельная'!E4 -> 71400 | D4: ='Статистика понедельная'!F4+'Статистика понедельная'!G4 -> 76600 | E4: ='Статистика понедельная'!H4+'Статистика понедельная'!I4 -> 60700 | F4: ='Статистика понедельная'!J4+'Статистика понедельная'!K4 -> 63900 | G4: ='Статистика понедельная'!L4+'Статистика понедельная'!M4 -> 93932 | H4: ='Статистика понедельная'!N4+'Статистика понедельная'!O4 -> 95100 | I4: ='Статистика понедельная'!P4+'Статистика понедельная'!Q4 -> 31200 | J4: ='Статистика понедельная'!R4+'Статистика понедельная'!S4 -> 22100 | K4: ='Статистика понедельная'!T4+'Статистика понедельная'!U4 -> 88900 | L4: ='Статистика понедельная'!V4+'Статистика понедельная'!W4 -> 66000 | M4: ='Статистика понедельная'!X4+'Статистика понедельная'!Y4 -> 50600
A5: Расходы дети | B5: ='Статистика понедельная'!B5+'Статистика понедельная'!C5 -> 18496 | C5: ='Статистика понедельная'!D5+'Статистика понедельная'!E5 -> 7000 | D5: ='Статистика понедельная'!F5+'Статистика понедельная'!G5 -> 7590 | E5: ='Статистика понедельная'!H5+'Статистика понедельная'!I5 -> 15400 | F5: ='Статистика понедельная'!J5+'Статистика понедельная'!K5 -> 24672 | G5: ='Статистика понедельная'!L5+'Статистика понедельная'!M5 -> 3400 | H5: ='Статистика понедельная'!N5+'Статистика понедельная'!O5 -> 0 | I5: ='Статистика понедельная'!P5+'Статистика понедельная'!Q5 -> 4550 | J5: ='Статистика понедельная'!R5+'Статистика понедельная'!S5 -> 8090 | K5: ='Статистика понедельная'!T5+'Статистика понедельная'!U5 -> 10644 | L5: ='Статистика понедельная'!V5+'Статистика понедельная'!W5 -> 9890 | M5: ='Статистика понедельная'!X5+'Статистика понедельная'!Y5 -> 15025
A6: Расходы еда и одежда | B6: ='Статистика понедельная'!B6+'Статистика понедельная'!C6 -> 49339 | C6: ='Статистика понедельная'!D6+'Статистика понедельная'!E6 -> 46814 | D6: ='Статистика понедельная'!F6+'Статистика понедельная'!G6 -> 42313 | E6: ='Статистика понедельная'!H6+'Статистика понедельная'!I6 -> 52629 | F6: ='Статистика понедельная'!J6+'Статистика понедельная'!K6 -> 27914 | G6: ='Статистика понедельная'!L6+'Статистика понедельная'!M6 -> 56323 | H6: ='Статистика понедельная'!N6+'Статистика понедельная'!O6 -> 50365 | I6: ='Статистика понедельная'!P6+'Статистика понедельная'!Q6 -> 34800 | J6: ='Статистика понедельная'!R6+'Статистика понедельная'!S6 -> 46637 | K6: ='Статистика понедельная'!T6+'Статистика понедельная'!U6 -> 51174 | L6: ='Статистика понедельная'!V6+'Статистика понедельная'!W6 -> 39478 | M6: ='Статистика понедельная'!X6+'Статистика понедельная'!Y6 -> 46526
A7: Расходы Комуналка | B7: ='Статистика понедельная'!B7+'Статистика понедельная'!C7 -> 2970 | C7: ='Статистика понедельная'!D7+'Статистика понедельная'!E7 -> 5090 | D7: ='Статистика понедельная'!F7+'Статистика понедельная'!G7 -> 5945 | E7: ='Статистика понедельная'!H7+'Статистика понедельная'!I7 -> 7750 | F7: ='Статистика понедельная'!J7+'Статистика понедельная'!K7 -> 5735 | G7: ='Статистика понедельная'!L7+'Статистика понедельная'!M7 -> 4840 | H7: ='Статистика понедельная'!N7+'Статистика понедельная'!O7 -> 3160 | I7: ='Статистика понедельная'!P7+'Статистика понедельная'!Q7 -> 2150 | J7: ='Статистика понедельная'!R7+'Статистика понедельная'!S7 -> 3120 | K7: ='Статистика понедельная'!T7+'Статистика понедельная'!U7 -> 1974 | L7: ='Статистика понедельная'!V7+'Статистика понедельная'!W7 -> 8521 | M7: ='Статистика понедельная'!X7+'Статистика понедельная'!Y7 -> 5800
A8: Расходы Авто и Дом | B8: ='Статистика понедельная'!B8+'Статистика понедельная'!C8 -> 3428 | C8: ='Статистика понедельная'!D8+'Статистика понедельная'!E8 -> 10344 | D8: ='Статистика понедельная'!F8+'Статистика понедельная'!G8 -> 18687 | E8: ='Статистика понедельная'!H8+'Статистика понедельная'!I8 -> 48947 | F8: ='Статистика понедельная'!J8+'Статистика понедельная'!K8 -> 28225 | G8: ='Статистика понедельная'!L8+'Статистика понедельная'!M8 -> 11509 | H8: ='Статистика понедельная'!N8+'Статистика понедельная'!O8 -> 42254 | I8: ='Статистика понедельная'!P8+'Статистика понедельная'!Q8 -> 7561 | J8: ='Статистика понедельная'!R8+'Статистика понедельная'!S8 -> 38199 | K8: ='Статистика понедельная'!T8+'Статистика понедельная'!U8 -> 3200 | L8: ='Статистика понедельная'!V8+'Статистика понедельная'!W8 -> 20281 | M8: ='Статистика понедельная'!X8+'Статистика понедельная'!Y8 -> 11479
A9: Отпуск | B9: ='Статистика понедельная'!B9+'Статистика понедельная'!C9 -> 0 | C9: ='Статистика понедельная'!D9+'Статистика понедельная'!E9 -> 5700 | D9: ='Статистика понедельная'!F9+'Статистика понедельная'!G9 -> 144903 | E9: ='Статистика понедельная'!H9+'Статистика понедельная'!I9 -> 18000 | F9: ='Статистика понедельная'!J9+'Статистика понедельная'!K9 -> 35932 | G9: ='Статистика понедельная'!L9+'Статистика понедельная'!M9 -> 21600 | H9: ='Статистика понедельная'!N9+'Статистика понедельная'!O9 -> 29125 | I9: ='Статистика понедельная'!P9+'Статистика понедельная'!Q9 -> 24977 | J9: ='Статистика понедельная'!R9+'Статистика понедельная'!S9 -> 0 | K9: ='Статистика понедельная'!T9+'Статистика понедельная'!U9 -> 0 | L9: ='Статистика понедельная'!V9+'Статистика понедельная'!W9 -> 20619 | M9: ='Статистика понедельная'!X9+'Статистика понедельная'!Y9 -> 0
A10: Доходы - Расходы | B10: ='Бюджет 2019'!D48+'Бюджет 2019'!E48 -> 4182 | C10: ='Бюджет 2019'!F48+'Бюджет 2019'!G48 -> -1649 | D10: ='Бюджет 2019'!H48+'Бюджет 2019'!I48 -> 28647 | E10: ='Бюджет 2019'!J48+'Бюджет 2019'!K48 -> 8632 | F10: ='Бюджет 2019'!L48+'Бюджет 2019'!M48 -> -10097 | G10: ='Бюджет 2019'!N48+'Бюджет 2019'!O48 -> -33246 | H10: ='Бюджет 2019'!P48+'Бюджет 2019'!Q48 -> 187246 | I10: ='Бюджет 2019'!R48+'Бюджет 2019'!S48 -> 29656 | J10: ='Бюджет 2019'!T48+'Бюджет 2019'!U48 -> -32111 | K10: ='Бюджет 2019'!V48+'Бюджет 2019'!W48 -> 12364 | L10: ='Бюджет 2019'!X48+'Бюджет 2019'!Y48 -> -6503 | M10: ='Бюджет 2019'!Z48+'Бюджет 2019'!AA48 -> -21104
A35: Доходы-Расходы

Sheet Статистика понедельная
B1: 1/2 январь | C1: 2/2 январь | D1: 1/2 февраль | E1: 2/2 февраль | F1: 1/2 март | G1: 2/2 март | H1: 1/2 апрель | I1: 2/2 апрель | J1: 1/2 май | K1: 2/2 май | L1: 1/2 июнь | M1: 2/2 июнь | N1: 1/2 июль | O1: 2/2 июль | P1: 1/2 август | Q1: 2/2 август | R1: 1/2 сентябрь | S1: 2/2 сентябрь | T1: 1/2 октябрь | U1: 2/2 октябрь | V1: 1/2 ноябрь | W1: 2/2 ноябрь | X1: 1/2 декабрь | Y1: 2/2 декабрь
A2: Доходы Работа | B2: ='Бюджет 2019'!D8+'Бюджет 2019'!D9+'Бюджет 2019'!D10+'Бюджет 2019'!D11+'Бюджет 2019'!D12 -> 72850 | C2: ='Бюджет 2019'!E8+'Бюджет 2019'!E9+'Бюджет 2019'!E10+'Бюджет 2019'!E11+'Бюджет 2019'!E12 -> 77700 | D2: ='Бюджет 2019'!F8+'Бюджет 2019'!F9+'Бюджет 2019'!F10+'Бюджет 2019'!F11+'Бюджет 2019'!F12 -> 44850 | E2: ='Бюджет 2019'!G8+'Бюджет 2019'!G9+'Бюджет 2019'!G10+'Бюджет 2019'!G11+'Бюджет 2019'!G12 -> 109680 | F2: ='Бюджет 2019'!H8+'Бюджет 2019'!H9+'Бюджет 2019'!H10+'Бюджет 2019'!H11+'Бюджет 2019'!H12 -> 39100 | G2: ='Бюджет 2019'!I8+'Бюджет 2019'!I9+'Бюджет 2019'!I10+'Бюджет 2019'!I11+'Бюджет 2019'!I12 -> 146280 | H2: ='Бюджет 2019'!J8+'Бюджет 2019'!J9+'Бюджет 2019'!J10+'Бюджет 2019'!J11+'Бюджет 2019'!J12 -> 39100 | I2: ='Бюджет 2019'!K8+'Бюджет 2019'!K9+'Бюджет 2019'!K10+'Бюджет 2019'!K11+'Бюджет 2019'!K12 -> 109000 | ... Y2: ='Бюджет 2019'!AA8+'Бюджет 2019'!AA9+'Бюджет 2019'!AA10+'Бюджет 2019'!AA11+'Бюджет 2019'!AA12 -> 114838
A3: Доходы Прочие | B3: ='Бюджет 2019'!D13+'Бюджет 2019'!D14+'Бюджет 2019'!D15 -> 737 | C3: ='Бюджет 2019'!E13+'Бюджет 2019'!E14+'Бюджет 2019'!E15 -> 82070 | D3: ='Бюджет 2019'!F13+'Бюджет 2019'!F14+'Бюджет 2019'!F15 -> 620 | E3: ='Бюджет 2019'!G13+'Бюджет 2019'!G14+'Бюджет 2019'!G15 -> 92 | F3: ='Бюджет 2019'!H13+'Бюджет 2019'!H14+'Бюджет 2019'!H15 -> 0 | G3: ='Бюджет 2019'!I13+'Бюджет 2019'!I14+'Бюджет 2019'!I15 -> 88 | H3: ='Бюджет 2019'!J13+'Бюджет 2019'!J14+'Бюджет 2019'!J15 -> 0 | I3: ='Бюджет 2019'!K13+'Бюджет 2019'!K14+'Бюджет 2019'!K15 -> 324 | ... L3: ='Бюджет 2019'!N13+'Бюджет 2019'!N14+'Бюджет 2019'!N15 -> 0 | M3: ='Бюджет 2019'!O13+'Бюджет 2019'!O14+'Бюджет 2019'!Q15 -> 308 | N3: ='Бюджет 2019'!P13+'Бюджет 2019'!P14+'Бюджет 2019'!R15 -> 1787 | O3: ='Бюджет 2019'!Q13+'Бюджет 2019'!Q14+#REF! -> #REF! | P3: ='Бюджет 2019'!R13+'Бюджет 2019'!R14+#REF! -> #REF! | Q3: ='Бюджет 2019'!S13+'Бюджет 2019'!S14+'Бюджет 2019'!S15 -> 985 | R3: ='Бюджет 2019'!T13+'Бюджет 2019'!T14+'Бюджет 2019'!T15 -> 85 | S3: ='Бюджет 2019'!U13+'Бюджет 2019'!U14+'Бюджет 2019'!U15 -> 120 | T3: ='Бюджет 2019'!V13+'Бюджет 2019'!V14+'Бюджет 2019'!V15 -> 0 | U3: ='Бюджет 2019'!W13+'Бюджет 2019'!W14+'Бюджет 2019'!W15 -> 1063 | V3: ='Бюджет 2019'!X13+'Бюджет 2019'!X14+'Бюджет 2019'!X15 -> 158 | W3: ='Бюджет 2019'!Y13+'Бюджет 2019'!Y14+'Бюджет 2019'!Y15 -> 11603 | X3: ='Бюджет 2019'!Z13+'Бюджет 2019'!Z14+'Бюджет 2019'!Z15 -> 1081 | Y3: ='Бюджет 2019'!AA13+'Бюджет 2019'!AA14+'Бюджет 2019'!AA15 -> 1226
A4: Накопления | B4: ='Бюджет 2019'!D22+'Бюджет 2019'!D23+'Бюджет 2019'!D24+'Бюджет 2019'!D19 -> 26000 | C4: ='Бюджет 2019'!E22+'Бюджет 2019'!E23+'Бюджет 2019'!E24+'Бюджет 2019'!E19 -> 125300 | D4: ='Бюджет 2019'!F22+'Бюджет 2019'!F23+'Бюджет 2019'!F24+'Бюджет 2019'!F19 -> 25300 | E4: ='Бюджет 2019'!G22+'Бюджет 2019'!G23+'Бюджет 2019'!G24+'Бюджет 2019'!G19 -> 46100 | F4: ='Бюджет 2019'!H22+'Бюджет 2019'!H23+'Бюджет 2019'!H24+'Бюджет 2019'!H19 -> 41300 | G4: ='Бюджет 2019'!I22+'Бюджет 2019'!I23+'Бюджет 2019'!I24+'Бюджет 2019'!I19 -> 35300 | H4: ='Бюджет 2019'!J22+'Бюджет 2019'!J23+'Бюджет 2019'!J24+'Бюджет 2019'!J19 -> 10100 | I4: ='Бюджет 2019'!K22+'Бюджет 2019'!K23+'Бюджет 2019'!K24+'Бюджет 2019'!K19 -> 50600 | ... Y4: ='Бюджет 2019'!AA22+'Бюджет 2019'!AA23+'Бюджет 2019'!AA24+'Бюджет 2019'!AA19 -> 32300
A5: Расходы дети | B5: ='Бюджет 2019'!D28+'Бюджет 2019'!D31+'Бюджет 2019'!D32+'Бюджет 2019'!D33+'Бюджет 2019'!D27+'Бюджет 2019'!D21 -> 5796 | C5: ='Бюджет 2019'!E28+'Бюджет 2019'!E31+'Бюджет 2019'!E32+'Бюджет 2019'!E33+'Бюджет 2019'!E27+'Бюджет 2019'!E21 -> 12700 | D5: ='Бюджет 2019'!F28+'Бюджет 2019'!F31+'Бюджет 2019'!F32+'Бюджет 2019'!F33+'Бюджет 2019'!F27+'Бюджет 2019'!F21 -> 2200 | E5: ='Бюджет 2019'!G28+'Бюджет 2019'!G31+'Бюджет 2019'!G32+'Бюджет 2019'!G33+'Бюджет 2019'!G27+'Бюджет 2019'!G21 -> 4800 | F5: ='Бюджет 2019'!H28+'Бюджет 2019'!H31+'Бюджет 2019'!H32+'Бюджет 2019'!H33+'Бюджет 2019'!H27+'Бюджет 2019'!H21 -> 3700 | G5: ='Бюджет 2019'!I28+'Бюджет 2019'!I31+'Бюджет 2019'!I32+'Бюджет 2019'!I33+'Бюджет 2019'!I27+'Бюджет 2019'!I21 -> 3890 | H5: ='Бюджет 2019'!J28+'Бюджет 2019'!J31+'Бюджет 2019'!J32+'Бюджет 2019'!J33+'Бюджет 2019'!J27+'Бюджет 2019'!J21 -> 9830 | I5: ='Бюджет 2019'!K28+'Бюджет 2019'!K31+'Бюджет 2019'!K32+'Бюджет 2019'!K33+'Бюджет 2019'!K27+'Бюджет 2019'!K21 -> 5570 | ... Y5: ='Бюджет 2019'!AA28+'Бюджет 2019'!AA31+'Бюджет 2019'!AA32+'Бюджет 2019'!AA33+'Бюджет 2019'!AA27+'Бюджет 2019'!AA21 -> 6630
A6: Расходы еда и одежда | B6: ='Бюджет 2019'!D34+'Бюджет 2019'!D43+'Бюджет 2019'!D45 -> 21967 | C6: ='Бюджет 2019'!E34+'Бюджет 2019'!E43+'Бюджет 2019'!E45 -> 27372 | D6: ='Бюджет 2019'!F34+'Бюджет 2019'!F43+'Бюджет 2019'!F45 -> 23119 | E6: ='Бюджет 2019'!G34+'Бюджет 2019'!G43+'Бюджет 2019'!G45 -> 23695 | F6: ='Бюджет 2019'!H34+'Бюджет 2019'!H43+'Бюджет 2019'!H45 -> 12432 | G6: ='Бюджет 2019'!I34+'Бюджет 2019'!I43+'Бюджет 2019'!I45 -> 29881 | H6: ='Бюджет 2019'!J34+'Бюджет 2019'!J43+'Бюджет 2019'!J45 -> 21937 | I6: ='Бюджет 2019'!K34+'Бюджет 2019'!K43+'Бюджет 2019'!K45 -> 30692 | ... Y6: ='Бюджет 2019'!AA34+'Бюджет 2019'!AA43+'Бюджет 2019'!AA45 -> 23127
A7: Расходы Комуналка | B7: ='Бюджет 2019'!D29+'Бюджет 2019'!D30 -> 0 | C7: ='Бюджет 2019'!E29+'Бюджет 2019'!E30 -> 2970 | D7: ='Бюджет 2019'!F29+'Бюджет 2019'!F30 -> 1000 | E7: ='Бюджет 2019'!G29+'Бюджет 2019'!G30 -> 4090 | F7: ='Бюджет 2019'!H29+'Бюджет 2019'!H30 -> 2550 | G7: ='Бюджет 2019'!I29+'Бюджет 2019'!I30 -> 3395 | H7: ='Бюджет 2019'!J29+'Бюджет 2019'!J30 -> 4350 | I7: ='Бюджет 2019'!K29+'Бюджет 2019'!K30 -> 3400 | ... Y7: ='Бюджет 2019'!AA29+'Бюджет 2019'!AA30 -> 1600
A8: Расходы Авто и Дом | B8: ='Бюджет 2019'!D36+'Бюджет 2019'!D37+'Бюджет 2019'!D38+'Бюджет 2019'!D40+'Бюджет 2019'!D41 -> 2803 | C8: ='Бюджет 2019'!E36+'Бюджет 2019'!E37+'Бюджет 2019'!E38+'Бюджет 2019'!E40+'Бюджет 2019'!E41 -> 625 | D8: ='Бюджет 2019'!F36+'Бюджет 2019'!F37+'Бюджет 2019'!F38+'Бюджет 2019'!F40+'Бюджет 2019'!F41 -> 5940 | E8: ='Бюджет 2019'!G36+'Бюджет 2019'!G37+'Бюджет 2019'!G38+'Бюджет 2019'!G40+'Бюджет 2019'!G41 -> 4404 | F8: ='Бюджет 2019'!H36+'Бюджет 2019'!H37+'Бюджет 2019'!H38+'Бюджет 2019'!H40+'Бюджет 2019'!H41 -> 13287 | G8: ='Бюджет 2019'!I36+'Бюджет 2019'!I37+'Бюджет 2019'!I38+'Бюджет 2019'!I40+'Бюджет 2019'!I41 -> 5400 | H8: ='Бюджет 2019'!J36+'Бюджет 2019'!J37+'Бюджет 2019'!J38+'Бюджет 2019'!J40+'Бюджет 2019'!J41 -> 28643 | I8: ='Бюджет 2019'!K36+'Бюджет 2019'!K37+'Бюджет 2019'!K38+'Бюджет 2019'!K40+'Бюджет 2019'!K41 -> 20304 | ... Y8: ='Бюджет 2019'!AA36+'Бюджет 2019'!AA37+'Бюджет 2019'!AA38+'Бюджет 2019'!AA40+'Бюджет 2019'!AA41 -> 4265
A9: Отпуск | B9: ='Бюджет 2019'!D46 | C9: ='Бюджет 2019'!E46 | D9: ='Бюджет 2019'!F46 -> 4200 | E9: ='Бюджет 2019'!G46 -> 1500 | F9: ='Бюджет 2019'!H46 | G9: ='Бюджет 2019'!I46 -> 144903 | H9: ='Бюджет 2019'!J46 -> 18000 | I9: ='Бюджет 2019'!K46 | ... Y9: ='Бюджет 2019'!AA46
A12: Доходы | H12: Расходы

Sheet Инвестиции
A1: Название актива | B1: Объект вложения | C1: Код актива | D1: Малый риск | E1: Средний риск | F1: Высокий риск | G1: Стоимость сбалансированного портфеля | H1: начало | I1: на 13.11.2016 | J1: Средний % годовых за весь срок | K1: Расчетная доходность за последний год | L1: Расчетная доходность за 5 лет | M1: Расчетная доходность за 10 лет | N1: стабильный рост (при стабильной валюте) | O1: % роста в портфеле малого риска | P1: % роста в портфеле среднего риска | Q1: % роста в портфеле высокого риска
A2: FinEx Tradable Russian Corporate Bonds UCITS ETF (RUB) | B2: Еврооблигации российских эмитентов с рублевым хеджем | C2: FXRB | D2: 0.15 | E2: 0.15 | F2: 0.05 | G2: =1208/F2 -> 24160 | H2: 1012 | I2: 1231 | J2: =(I2/H2-1)/2.7 -> 0.080149319 | K2: 13,39% | L2: 32,50% | M2: 56,04% | N2: + | O2: =$J2*D2 -> 0.012022398 | P2: =$J2*E2 -> 0.012022398 | Q2: =$J2*F2 -> 0.004007466
A3: FinEx MSCI USA UCITS ETF | B3: Акции / США | C3: FXUS | D3: 0.185 | E3: 0.22 | F3: 0.1 | G3: =2490/F3 -> 24900 | H3: 30 | I3: 36.7 | J3: =(I3/H3-1)/2.7 -> 0.082716049 | K3: 5,62% | L3: 0.84 | M3: 83,51% | N3: - | O3: =$J3*D3 -> 0.015302469 | P3: =$J3*E3 -> 0.018197531 | Q3: =$J3*F3 -> 0.0082716049
A4: FinEx MSCI USA Information Technology UCITS ETF | B4: Акции / ИТ-Сектор США | C4: FXIT | D4: 0.05 | E4: 0.13 | F4: 0.2 | G4: =2890/F4 -> 14450 | H4: 30 | I4: 42 | J4: =(I4/H4-1)/2.7 -> 0.14814815 | K4: 8,11% | L4: 96,58% | N4: +/- | O4: =$J4*D4 -> 0.0074074074 | P4: =$J4*E4 -> 0.019259259 | Q4: =$J4*F4 -> 0.02962963
A5: FinEx Gold ETF | B5: Золото | C5: FXGD | D5: 0.15 | E5: 0.084 | F5: 0.05 | G5: =542/F5 -> 10840 | H5: 10 | I5: 9.16 | J5: =(I5/H5-1)/2.7 -> -0.031111111 | K5: -2,19% | L5: -28,82% | M5: 98,16% | N5: - | O5: =$J5*D5 -> -0.0046666667 | P5: =$J5*E5 -> -0.0026133333 | Q5: =$J5*F5 -> -0.0015555556
A6: FinEx MSCI Japan UCITS ETF | B6: Акции / Япония | C6: FXJP | D6: 0.115 | E6: 0.066 | F6: 0.05 | G6: =2006/F6 -> 40120 | H6: 30 | I6: 31.83 | J6: =(I6/H6-1)/2.7 -> 0.022592593 | K6: 0,35% | L6: 46,94% | M6: 10,49% | N6: - | O6: =$J6*D6 -> 0.0025981481 | P6: =$J6*E6 -> 0.0014911111 | Q6: =$J6*F6 -> 0.0011296296
A7: FinEx Russian RTS Equity UCITS ETF (USD)​ | B7: Акции/Россия | C7: FXRL | D7: 0.05 | E7: 0.05 | F7: 0.08 | G7: =1819/F7 -> 22737.5 | H7: 20 | I7: 26.75 | J7: =(I7/H7-1)/((11-3)/12) -> 0.50625 | K7: 14,71% | L7: -36,62% | M7: -43,16% | N7: - | O7: =$J7*D7 -> 0.0253125 | P7: =$J7*E7 -> 0.0253125 | Q7: =$J7*F7 -> 0.0405
A8: FinEx MSCI China UCITS ETF | B8: Акции / Китай | C8: FXCN | D8: 0.05 | E8: 0.05 | F8: 0.05 | G8: =1915/F8 -> 38300 | H8: 30 | I8: 29.85 | J8: =(I8/H8-1)/2 -> -0.0025 | K8: -0,58% | L8: 25,41% | M8: 79,24% | N8: - | O8: =$J8*D8 -> -0.000125 | P8: =$J8*E8 -> -0.000125 | Q8: =$J8*F8 -> -0.000125
A9: FinEx MSCI Australia UCITS ETF | B9: Акции / Австралия | C9: FXAU | D9: 0.05 | E9: 0.05 | F9: 0.05 | G9: =1607/F9 -> 32140 | H9: 30 | I9: 24.58 | J9: =(I9/H9-1)/2.7 -> -0.06691358 | K9: -2,84% | L9: 72,91% | M9: 52,46% | N9: - | O9: =$J9*D9 -> -0.003345679 | P9: =$J9*E9 -> -0.003345679 | Q9: =$J9*F9 -> -0.003345679
A10: FinEx MSCI United Kingdom UCITS ETF | B10: Акции / Великобритания | C10: FXUK | D10: 0.05 | E10: 0.05 | F10: 0.18 | G10: =1652/F10 -> 9177.7778 | H10: 19 | I10: 20.42 | J10: =(I10/H10-1)/2.2 -> 0.033971292 | K10: 11,29% | L10: 44,84% | M10: 55,07% | N10: - | O10: =$J10*D10 -> 0.0016985646 | P10: =$J10*E10 -> 0.0016985646 | Q10: =$J10*F10 -> 0.0061148325
A11: FinEx MSCI Germany UCITS ETF | B11: Акции / Германия | C11: FXDE | D11: 0.05 | E11: 0.05 | F11: 0.14 | G11: =1752/F11 -> 12514.286 | H11: 22 | I11: 24.87 | J11: =(I11/H11-1)/2.2 -> 0.059297521 | K11: 16,48% | L11: 13,99% | M11: 47,19% | N11: - | O11: =$J11*D11 -> 0.002964876 | P11: =$J11*E11 -> 0.002964876 | Q11: =$J11*F11 -> 0.0083016529
A12: инвестиционный фонд ФинЭкс денежного рынка | C12: FXMM | D12: 0.1 | E12: 0.1 | F12: 0.05 | G12: =1290/F12 -> 25800 | H12: 1000 | I12: 1284 | J12: =(I12/H12-1)/2.2 -> 0.12909091 | K12: 7,06% | L12: 0.33 | N12: + | O12: =$J12*D12 -> 0.012909091 | P12: =$J12*E12 -> 0.012909091 | Q12: =$J12*F12 -> 0.0064545455
F13: Минимальный портфель | G13: =MAX(G2:G12) -> 40120 | N13: Рост % годовых | O13: =SUM(O2:O12) -> 0.072078108 | P13: =SUM(P2:P12) -> 0.087771318 | Q13: =SUM(Q2:Q12) -> 0.099383126
